2019-03-26 00:45:45 ERROR (MainThread) [homeassistant.components.updater] Got unexpected response: None
2019-03-26 00:45:45 WARNING (Thread-23) [pychromecast.socket_client] [Sala:8009] Heartbeat timeout, resetting connection
2019-03-26 00:45:45 WARNING (Thread-24) [pychromecast.socket_client] [Miguel:8009] Heartbeat timeout, resetting connection
2019-03-26 00:45:45 WARNING (Thread-25) [pychromecast.socket_client] [Sala e Miguel:42981] Heartbeat timeout, resetting connection
2019-03-26 00:45:46 WARNING (Thread-26) [pychromecast.socket_client] [Suite Master:8009] Heartbeat timeout, resetting connection
2019-03-26 00:48:19 ERROR (MainThread) [homeassistant.helpers.entity] Update for switch.abajur_mesa fails
Traceback (most recent call last):
  File "/srv/homeassistant/lib/python3.5/site-packages/homeassistant/helpers/entity.py", line 220, in async_update_ha_state
    await self.async_device_update()
  File "/srv/homeassistant/lib/python3.5/site-packages/homeassistant/helpers/entity.py", line 348, in async_device_update
    await self.hass.async_add_executor_job(self.update)
  File "/usr/lib/python3.5/asyncio/futures.py", line 380, in __iter__
    yield self  # This tells Task to wait for completion.
  File "/usr/lib/python3.5/asyncio/tasks.py", line 304, in _wakeup
    future.result()
  File "/usr/lib/python3.5/asyncio/futures.py", line 293, in result
    raise self._exception
  File "/usr/lib/python3.5/concurrent/futures/thread.py", line 55, in run
    result = self.fn(*self.args, **self.kwargs)
  File "/srv/homeassistant/lib/python3.5/site-packages/homeassistant/components/switch/broadlink.py", line 304, in update
    self._update()
  File "/srv/homeassistant/lib/python3.5/site-packages/homeassistant/components/switch/broadlink.py", line 309, in _update
    state = self._device.check_power()
  File "/srv/homeassistant/lib/python3.5/site-packages/broadlink/__init__.py", line 416, in check_power
    response = self.send_packet(0x6a, packet)
  File "/srv/homeassistant/lib/python3.5/site-packages/broadlink/__init__.py", line 303, in send_packet
    self.cs.sendto(packet, self.host)
OSError: [Errno 101] Network is unreachable
2019-03-26 00:48:29 WARNING (Thread-23) [pychromecast.socket_client] [Sala:8009] Heartbeat timeout, resetting connection
2019-03-26 00:48:29 WARNING (Thread-24) [pychromecast.socket_client] [Miguel:8009] Heartbeat timeout, resetting connection
2019-03-26 00:48:29 ERROR (Thread-23) [pychromecast.socket_client] [Sala:8009] Failed to connect to service Insignia-NS-CSPGASP2-50c7c9e730be7982b9fc60438f4e5e39._googlecast._tcp.local., retrying in 5.0s
2019-03-26 00:48:29 ERROR (Thread-24) [pychromecast.socket_client] [Miguel:8009] Failed to connect to service Insignia-NS-CSPGASP-84d4fd1b0f0dc952b1799ff5a8e0c890._googlecast._tcp.local., retrying in 5.0s
2019-03-26 00:48:29 WARNING (Thread-25) [pychromecast.socket_client] [Sala e Miguel:42981] Heartbeat timeout, resetting connection
2019-03-26 00:48:29 ERROR (Thread-25) [pychromecast.socket_client] [Sala e Miguel:42981] Failed to connect to service Google-Cast-Group-993F587CDD5540F7BA9E8CE2131A18BE-1._googlecast._tcp.local., retrying in 5.0s
2019-03-26 00:48:29 WARNING (Thread-26) [pychromecast.socket_client] [Suite Master:8009] Heartbeat timeout, resetting connection
2019-03-26 00:48:29 ERROR (Thread-26) [pychromecast.socket_client] [Suite Master:8009] Failed to connect to service Insignia-NS-CSPGASP-0317116a2d8b403a4f71a99d5578786d._googlecast._tcp.local., retrying in 5.0s
